<!DOCTYPE html PUBLIC "-//W3C//DTD HTML 4.01//EN" "http://www.w3.org/TR/html4/strict.dtd">
<html>
<head>
<meta http-equiv="Content-Type" content="text/html; charset=utf-8">
<meta http-equiv="X-UA-Compatible" content="IE=edge">

<script type="text/javascript" src="../sh_main.js"></script>
<script type="text/javascript" src="../sh_cpp.js"></script>
<!--[IF IE]>
	<script type="text/javascript" src="ierange.js"></script>
<![ENDIF]-->
<script type="text/javascript" src="../masha.min.js"></script>
<script type="text/javascript" src="../all_pack.js"></script>
<link rel="stylesheet" type="text/css" href="../css/masha.css">
<link rel="stylesheet" type="text/css" href="../sh_print.css">
<link rel="stylesheet" type="text/css" href="../toc.css">
<link rel="stylesheet" type="text/css" href="../styles.css">
<script type="text/javascript" src="../page.js"></script>

<title>Throwing an exception</title>
</head>
<body>
<h2>
<dfn class="label">[except.throw]</dfn><object type="application/x-oleobject" classid="clsid:1e2a7bd0-dab9-11d0-b93a-00c04fc99f9e"><param name="Keyword" value="[except.throw]"></object>15.1 Throwing an exception </h2>

<p><a class="anchor" id="p1" href="#p1">1</a>Throwing an exception transfers control to a handler. An object is passed and the type of that object
determines which handlers can catch it.</p>

<div class="example">
<p>[ <em>Example:</em> </p>
<pre><code class="sh_cpp">throw "Help!";</code></pre>

<p>can be caught by a <i class="nonterminal">handler</i> of <code class="sh_cpp">const char*</code> type:</p>

<pre><code class="sh_cpp">try {
    // …
}
catch(const char* p) {
    // handle character string exceptions here
}</code></pre>

<p>and</p>

<pre><code class="sh_cpp">class Overflow {
public:
    Overflow(char,double,double);
};

void f(double x) {
    throw Overflow('+',x,3.45e107);
}</code></pre>

<p>can be caught by a handler for exceptions of type <code class="sh_cpp">Overflow</code></p>

<pre><code class="sh_cpp">try {
    f(1.2);
} catch(Overflow&amp; oo) {
    // handle exceptions of type Overflow here
}</code></pre>
<p> — <em>end example</em> ]</p>
</div>

<p><a class="anchor" id="p2" href="#p2">2</a>When an exception is thrown, control is transferred to the nearest handler with a matching type
(<a title="except.handle" href="except.handle.html">15.3</a>); “nearest” means the handler for which the <i class="nonterminal">compound-statement</i> or <i class="nonterminal">ctor-initializer</i>
following the <code class="sh_cpp">try</code> keyword was most recently entered by the thread of control and not yet exited.</p>

<p><a class="anchor" id="p3" href="#p3">3</a>A <i class="nonterminal">throw-expression</i> initializes a temporary object, called the <dfn>exception object</dfn><object type="application/x-oleobject" classid="clsid:1e2a7bd0-dab9-11d0-b93a-00c04fc99f9e"><param name="Keyword" value="exception object"></object>, the type of
which is determined by removing any top-level <i class="nonterminal">cv-qualifier</i>s from the static type of the operand of
<code class="sh_cpp">throw</code> and adjusting the type from “array of <code class="sh_cpp">T</code>” or “function returning <code class="sh_cpp">T</code>” to
“pointer to <code class="sh_cpp">T</code>” or “pointer to function returning <code class="sh_cpp">T</code>”, respectively. The temporary is an lvalue
and is used to initialize the variable named in the matching <i class="nonterminal">handler</i> (<a title="except.handle" href="except.handle.html">15.3</a>). If the type of the
exception object would be an incomplete type or a pointer to an incomplete type other than (possibly cv-qualified)
<code class="sh_cpp">void</code> the program is ill-formed. Except for these restrictions and the restrictions on type matching
mentioned in <a title="except.handle" href="except.handle.html">15.3</a>, the operand of <code class="sh_cpp">throw</code> is treated exactly as a function argument in a call
(<a title="expr.call" href="expr.call.html">5.2.2</a>) or the operand of a <code class="sh_cpp">return</code> statement.</p>

<p><a class="anchor" id="p4" href="#p4">4</a>The memory for the exception object is allocated in an unspecified way, except as noted in <a title="basic.stc.dynamic.allocation" href="basic.stc.dynamic.allocation.html">3.7.4.1</a>.
If a handler exits by rethrowing, control is passed to another handler for the same exception. The exception object is
destroyed after either the last remaining active handler for the exception exits by any means other than rethrowing, or
the last object of type <code class="sh_cpp">std::exception_ptr</code> (<a title="propagation" href="propagation.html">18.8.5</a>) that refers to the exception object is
destroyed, whichever is later. In the former case, the destruction occurs when the handler exits, immediately after the
destruction of the object declared in the <i class="nonterminal">exception-declaration</i> in the handler, if any. In the latter case, the
destruction occurs before the destructor of <code class="sh_cpp">std::exception_ptr</code> returns. The implementation may then
deallocate the memory for the exception object; any such deallocation is done in an unspecified way. <span class="note">[ <em>Note:</em> an exception
thrown by a <i class="nonterminal">throw-expression</i> does not propagate to other threads unless caught, stored, and rethrown using
appropriate library functions; see <a title="propagation" href="propagation.html">18.8.5</a> and <a title="futures" href="futures.overview.html">30.6</a>. — <em>end note</em> ]</span></p>

<p><a class="anchor" id="p5" href="#p5">5</a>When the thrown object is a class object, the copy/move constructor and the destructor shall be accessible,
even if the copy/move operation is elided (<a title="class.copy" href="class.copy.html">12.8</a>).</p>

<p><a class="anchor" id="p6" href="#p6">6</a>An exception is considered caught when a handler for that exception becomes active (<a title="except.handle" href="except.handle.html">15.3</a>). <span class="note">[ <em>Note:</em> An
exception can have active handlers and still be considered uncaught if it is rethrown. — <em>end note</em> ]</span></p>

<p><a class="anchor" id="p7" href="#p7">7</a>If the exception handling mechanism, after completing evaluation of the expression to be thrown but before the
exception is caught, calls a function that exits via an exception, <code class="sh_cpp">std::terminate</code> is called
(<a title="except.terminate" href="except.terminate.html">15.5.1</a>).</p>

<div class="example">
<p>[ <em>Example:</em> </p>
<pre><code class="sh_cpp">struct C {
  C() { }
  C(const C&amp;) { throw 0; }
};

int main() {
  try {
    throw C();      // calls std::terminate()
  } catch(C) { }
}</code></pre>
<p> — <em>end example</em> ]</p>
</div>

<p><a class="anchor" id="p8" href="#p8">8</a>A <i class="nonterminal">throw-expression</i> with no operand rethrows the currently handled exception (<a title="except.handle" href="except.handle.html">15.3</a>). The
exception is reactivated with the existing temporary; no new temporary exception object is created. The exception is no
longer considered to be caught; therefore, the value of <code class="sh_cpp">std::uncaught_exception()</code> will again be
<code class="sh_cpp">true</code>.</p>

<div class="example">
<p>[ <em>Example:</em> code that must be executed because of an exception yet cannot completely handle the exception can be written
like this:</p>

<pre><code class="sh_cpp">try {
    // …
} catch (...) {     // catch all exceptions
  // respond (partially) to exception
  throw;            // pass the exception to some
                    // other handler
}</code></pre>
<p> — <em>end example</em> ]</p>
</div>

<p><a class="anchor" id="p9" href="#p9">9</a>If no exception is presently being handled, executing a <i class="nonterminal">throw-expression</i> with no operand calls
<code class="sh_cpp">std::terminate()</code> (<a title="except.terminate" href="except.terminate.html">15.5.1</a>).</p>
</body>
</html>



